Traceback (most recent call last):
  File "/opt/anaconda3/lib/python3.12/site-packages/jupyter_cache/executors/utils.py", line 58, in single_nb_execution
    executenb(
  File "/opt/anaconda3/lib/python3.12/site-packages/nbclient/client.py", line 1305, in execute
    return NotebookClient(nb=nb, resources=resources, km=km, **kwargs).execute()
           ^^^^^^^^^^^^^^^^^^^^^^^^^^^^^^^^^^^^^^^^^^^^^^^^^^^^^^^^^^^^^^^^^^^^^
  File "/opt/anaconda3/lib/python3.12/site-packages/jupyter_core/utils/__init__.py", line 165, in wrapped
    return loop.run_until_complete(inner)
           ^^^^^^^^^^^^^^^^^^^^^^^^^^^^^^
  File "/opt/anaconda3/lib/python3.12/asyncio/base_events.py", line 687, in run_until_complete
    return future.result()
           ^^^^^^^^^^^^^^^
  File "/opt/anaconda3/lib/python3.12/site-packages/nbclient/client.py", line 705, in async_execute
    await self.async_execute_cell(
  File "/opt/anaconda3/lib/python3.12/site-packages/nbclient/client.py", line 1058, in async_execute_cell
    await self._check_raise_for_error(cell, cell_index, exec_reply)
  File "/opt/anaconda3/lib/python3.12/site-packages/nbclient/client.py", line 914, in _check_raise_for_error
    raise CellExecutionError.from_cell_and_msg(cell, exec_reply_content)
nbclient.exceptions.CellExecutionError: An error occurred while executing the following cell:
------------------
from PIL import Image
from IPython.display import display
img = Image.open('figuur-2.png')
display(img)
------------------


[0;31m---------------------------------------------------------------------------[0m
[0;31mFileNotFoundError[0m                         Traceback (most recent call last)
Cell [0;32mIn[1], line 3[0m
[1;32m      1[0m [38;5;28;01mfrom[39;00m [38;5;21;01mPIL[39;00m [38;5;28;01mimport[39;00m Image
[1;32m      2[0m [38;5;28;01mfrom[39;00m [38;5;21;01mIPython[39;00m[38;5;21;01m.[39;00m[38;5;21;01mdisplay[39;00m [38;5;28;01mimport[39;00m display
[0;32m----> 3[0m img [38;5;241m=[39m Image[38;5;241m.[39mopen([38;5;124m'[39m[38;5;124mfiguur-2.png[39m[38;5;124m'[39m)
[1;32m      4[0m display(img)

File [0;32m/opt/anaconda3/lib/python3.12/site-packages/PIL/Image.py:3431[0m, in [0;36mopen[0;34m(fp, mode, formats)[0m
[1;32m   3428[0m     filename [38;5;241m=[39m os[38;5;241m.[39mpath[38;5;241m.[39mrealpath(os[38;5;241m.[39mfspath(fp))
[1;32m   3430[0m [38;5;28;01mif[39;00m filename:
[0;32m-> 3431[0m     fp [38;5;241m=[39m builtins[38;5;241m.[39mopen(filename, [38;5;124m"[39m[38;5;124mrb[39m[38;5;124m"[39m)
[1;32m   3432[0m     exclusive_fp [38;5;241m=[39m [38;5;28;01mTrue[39;00m
[1;32m   3433[0m [38;5;28;01melse[39;00m:

[0;31mFileNotFoundError[0m: [Errno 2] No such file or directory: '/Users/merlijn11erink/mynewbook/figuur-2.png'

